{
 "cells": [
  {
   "cell_type": "code",
   "execution_count": 1,
   "metadata": {},
   "outputs": [
    {
     "ename": "ModuleNotFoundError",
     "evalue": "No module named 'pymongo'",
     "output_type": "error",
     "traceback": [
      "\u001b[1;31m---------------------------------------------------------------------------\u001b[0m",
      "\u001b[1;31mModuleNotFoundError\u001b[0m                       Traceback (most recent call last)",
      "\u001b[1;32m<ipython-input-1-c275cfc49946>\u001b[0m in \u001b[0;36m<module>\u001b[1;34m()\u001b[0m\n\u001b[1;32m----> 1\u001b[1;33m \u001b[1;32mimport\u001b[0m \u001b[0mpymongo\u001b[0m\u001b[1;33m\u001b[0m\u001b[0m\n\u001b[0m",
      "\u001b[1;31mModuleNotFoundError\u001b[0m: No module named 'pymongo'"
     ]
    }
   ],
   "source": [
    "import pymongo"
   ]
  },
  {
   "cell_type": "code",
   "execution_count": 2,
   "metadata": {},
   "outputs": [
    {
     "name": "stdout",
     "output_type": "stream",
     "text": [
      "Collecting pymongo\n"
     ]
    },
    {
     "name": "stderr",
     "output_type": "stream",
     "text": [
      "  Retrying (Retry(total=4, connect=None, read=None, redirect=None, status=None)) after connection broken by 'NewConnectionError('<pip._vendor.urllib3.connection.VerifiedHTTPSConnection object at 0x000001473B1945F8>: Failed to establish a new connection: [Errno 11001] getaddrinfo failed')': /simple/pymongo/\n",
      "  Retrying (Retry(total=3, connect=None, read=None, redirect=None, status=None)) after connection broken by 'NewConnectionError('<pip._vendor.urllib3.connection.VerifiedHTTPSConnection object at 0x000001473B194358>: Failed to establish a new connection: [Errno 11001] getaddrinfo failed')': /simple/pymongo/\n",
      "  Retrying (Retry(total=2, connect=None, read=None, redirect=None, status=None)) after connection broken by 'NewConnectionError('<pip._vendor.urllib3.connection.VerifiedHTTPSConnection object at 0x000001473B1942B0>: Failed to establish a new connection: [Errno 11001] getaddrinfo failed')': /simple/pymongo/\n",
      "  Retrying (Retry(total=1, connect=None, read=None, redirect=None, status=None)) after connection broken by 'NewConnectionError('<pip._vendor.urllib3.connection.VerifiedHTTPSConnection object at 0x000001473B1944A8>: Failed to establish a new connection: [Errno 11001] getaddrinfo failed')': /simple/pymongo/\n",
      "  Retrying (Retry(total=0, connect=None, read=None, redirect=None, status=None)) after connection broken by 'NewConnectionError('<pip._vendor.urllib3.connection.VerifiedHTTPSConnection object at 0x000001473B194A20>: Failed to establish a new connection: [Errno 11001] getaddrinfo failed')': /simple/pymongo/\n",
      "  Could not find a version that satisfies the requirement pymongo (from versions: )\n",
      "No matching distribution found for pymongo\n"
     ]
    }
   ],
   "source": [
    "!pip install pymongo"
   ]
  },
  {
   "cell_type": "code",
   "execution_count": null,
   "metadata": {},
   "outputs": [],
   "source": []
  }
 ],
 "metadata": {
  "kernelspec": {
   "display_name": "Python 3",
   "language": "python",
   "name": "python3"
  },
  "language_info": {
   "codemirror_mode": {
    "name": "ipython",
    "version": 3
   },
   "file_extension": ".py",
   "mimetype": "text/x-python",
   "name": "python",
   "nbconvert_exporter": "python",
   "pygments_lexer": "ipython3",
   "version": "3.7.0"
  }
 },
 "nbformat": 4,
 "nbformat_minor": 1
}
